<sdf version='1.7'>
  <world name='default'>
    <model name='ground_plane'>
      <static>1</static>
      <link name='link'>
        <collision name='collision'>
          <geometry>
            <plane>
              <normal>0 0 1</normal>
              <size>100 100</size>
            </plane>
          </geometry>
          <surface>
            <contact>
              <collide_bitmask>65535</collide_bitmask>
              <ode/>
            </contact>
            <friction>
              <ode>
                <mu>100</mu>
                <mu2>50</mu2>
              </ode>
              <torsional>
                <ode/>
              </torsional>
            </friction>
            <bounce/>
          </surface>
          <max_contacts>10</max_contacts>
        </collision>
        <visual name='visual'>
          <cast_shadows>0</cast_shadows>
          <geometry>
            <plane>
              <normal>0 0 1</normal>
              <size>100 100</size>
            </plane>
          </geometry>
          <material>
            <script>
              <uri>file://media/materials/scripts/gazebo.material</uri>
              <name>Gazebo/Grey</name>
            </script>
          </material>
        </visual>
        <self_collide>0</self_collide>
        <enable_wind>0</enable_wind>
        <kinematic>0</kinematic>
      </link>
    </model>
    <light name='sun' type='directional'>
      <cast_shadows>1</cast_shadows>
      <pose>0 0 10 0 -0 0</pose>
      <diffuse>0.8 0.8 0.8 1</diffuse>
      <specular>0.2 0.2 0.2 1</specular>
      <attenuation>
        <range>1000</range>
        <constant>0.9</constant>
        <linear>0.01</linear>
        <quadratic>0.001</quadratic>
      </attenuation>
      <direction>-0.5 0.1 -0.9</direction>
      <spot>
        <inner_angle>0</inner_angle>
        <outer_angle>0</outer_angle>
        <falloff>0</falloff>
      </spot>
    </light>
    <scene>
      <shadows>0</shadows>
      <ambient>0.4 0.4 0.4 1</ambient>
      <background>0.7 0.7 0.7 1</background>
    </scene>
    <model name='box'>
      <static>1</static>
      <pose>1 1 0 0 0.1 0</pose>
      <link name='link'>
        <collision name='collision'>
          <geometry>
            <box>
              <size>1 0.5 0.1</size>
            </box>
          </geometry>
          <max_contacts>10</max_contacts>
          <surface>
            <contact>
              <ode/>
            </contact>
            <bounce/>
            <friction>
              <torsional>
                <ode/>
              </torsional>
              <ode/>
            </friction>
          </surface>
        </collision>
        <visual name='visual'>
          <geometry>
            <box>
              <size>1 0.5 0.1</size>
            </box>
          </geometry>
          <cast_shadows>0</cast_shadows>
        </visual>
        <self_collide>0</self_collide>
        <enable_wind>0</enable_wind>
        <kinematic>0</kinematic>
      </link>
    </model>
    <gravity>0 0 -9.8</gravity>
    <magnetic_field>6e-06 2.3e-05 -4.2e-05</magnetic_field>
    <atmosphere type='adiabatic'/>
    <physics type='ode'>
      <max_step_size>0.001</max_step_size>
      <real_time_factor>1</real_time_factor>
      <real_time_update_rate>1000</real_time_update_rate>
    </physics>
    <wind/>
    <spherical_coordinates>
      <surface_model>EARTH_WGS84</surface_model>
      <latitude_deg>0</latitude_deg>
      <longitude_deg>0</longitude_deg>
      <elevation>0</elevation>
      <heading_deg>0</heading_deg>
    </spherical_coordinates>
    <model name='notspot_gazebo'>
      <link name='base_link'>
        <inertial>
          <pose>-0.000428 8.1e-05 0.000753 0 -0 0</pose>
          <mass>0.91776</mass>
          <inertia>
            <ixx>0.000662598</ixx>
            <ixy>-1.00061e-06</ixy>
            <ixz>-1.93134e-07</ixz>
            <iyy>0.000374868</iyy>
            <iyz>7.05922e-08</iyz>
            <izz>0.000763551</izz>
          </inertia>
        </inertial>
        <collision name='base_link_collision'>
          <pose>0 0 0.0275 0 -0 0</pose>
          <geometry>
            <box>
              <size>0.25 0.1285 0.055</size>
            </box>
          </geometry>
          <surface>
            <contact>
              <ode/>
            </contact>
            <friction>
              <ode/>
              <torsional>
                <ode/>
              </torsional>
            </friction>
            <bounce/>
          </surface>
          <max_contacts>10</max_contacts>
        </collision>
        <collision name='base_link_fixed_joint_lump__laser_frame_collision_1'>
          <pose>0 0 0.005 0 -0 0</pose>
          <geometry>
            <cylinder>
              <length>0.04</length>
              <radius>0.05</radius>
            </cylinder>
          </geometry>
          <surface>
            <contact>
              <ode/>
            </contact>
            <friction>
              <ode/>
              <torsional>
                <ode/>
              </torsional>
            </friction>
            <bounce/>
          </surface>
          <max_contacts>10</max_contacts>
        </collision>
        <visual name='base_link_visual'>
          <pose>0 0 0 0 -0 0</pose>
          <geometry>
            <mesh>
              <scale>1 1 1</scale>
              <uri>/home/liamo/Quadruped-Robot-Project/notspot_sim_py/src/notspot_description/meshes/body_obj.obj</uri>
            </mesh>
          </geometry>
        </visual>
        <visual name='base_link_fixed_joint_lump__camera_link_visual_1'>
          <pose>0.13 0 0.005 0 -0 0</pose>
          <geometry>
            <box>
              <size>0.01 0.03 0.03</size>
            </box>
          </geometry>
          <material>
            <script>
              <name>Gazebo/Blue</name>
              <uri>file://media/materials/scripts/gazebo.material</uri>
            </script>
          </material>
        </visual>
        <visual name='base_link_fixed_joint_lump__laser_frame_visual_2'>
          <pose>0 0 0.005 0 -0 0</pose>
          <geometry>
            <cylinder>
              <length>0.04</length>
              <radius>0.03</radius>
            </cylinder>
          </geometry>
          <material>
            <script>
              <name>Gazebo/Green</name>
              <uri>file://media/materials/scripts/gazebo.material</uri>
            </script>
          </material>
        </visual>
        <visual name='base_link_fixed_joint_lump__laser_frame_visual_3'>
          <pose>0 0 -0.005 0 -0 0</pose>
          <geometry>
            <cylinder>
              <length>0.05</length>
              <radius>0.01</radius>
            </cylinder>
          </geometry>
          <material>
            <script>
              <name>Gazebo/Green</name>
              <uri>file://media/materials/scripts/gazebo.material</uri>
            </script>
          </material>
        </visual>
        <gravity>1</gravity>
        <sensor name='imu_sensor' type='imu'>
          <always_on>1</always_on>
          <update_rate>100</update_rate>
          <visualize>1</visualize>
          <topic>__default_topic__</topic>
          <plugin name='imu_plugin' filename='libgazebo_ros_imu_sensor.so'>
            <topicName>notspot_imu/base_link_orientation</topicName>
            <bodyName>imu_link</bodyName>
            <updateRateHZ>15.0</updateRateHZ>
            <gaussianNoise>0.0</gaussianNoise>
            <xyzOffset>0 0 0</xyzOffset>
            <rpyOffset>0 0 0</rpyOffset>
            <frameName>base_link</frameName>
            <initialOrientationAsReference>0</initialOrientationAsReference>
            <robotNamespace>/</robotNamespace>
          </plugin>
          <pose>0 0 0 0 -0 0</pose>
          <imu/>
        </sensor>
        <sensor name='camera' type='camera'>
          <visualize>1</visualize>
          <update_rate>10</update_rate>
          <camera>
            <horizontal_fov>2.09</horizontal_fov>
            <image>
              <format>R8G8B8</format>
              <width>640</width>
              <height>480</height>
            </image>
            <clip>
              <near>0.05</near>
              <far>20</far>
            </clip>
            <distortion>
              <k1>-0.2</k1>
              <k2>0.12</k2>
              <k3>0</k3>
              <p1>0</p1>
              <p2>0</p2>
              <center>0.5 0.5</center>
            </distortion>
            <noise>
              <type>gaussian</type>
              <mean>0</mean>
              <stddev>0.01</stddev>
            </noise>
          </camera>
          <plugin name='camera_controller' filename='libgazebo_ros_camera.so'>
            <frame_name>camera_link_optical</frame_name>
            <imageTopicName>/camera/image_raw</imageTopicName>
            <cameraInfoTopicName>/camera/camera_info</cameraInfoTopicName>
            <updateRate>10.0</updateRate>
            <robotNamespace>/</robotNamespace>
          </plugin>
          <pose>0.13 0 0.005 0 -0.1745 0</pose>
        </sensor>
        <sensor name='laser' type='ray'>
          <visualize>0</visualize>
          <update_rate>5</update_rate>
          <ray>
            <scan>
              <horizontal>
                <samples>90</samples>
                <min_angle>-3.14</min_angle>
                <max_angle>3.14</max_angle>
                <resolution>1</resolution>
              </horizontal>
              <vertical>
                <samples>1</samples>
                <min_angle>0</min_angle>
                <max_angle>0</max_angle>
              </vertical>
            </scan>
            <range>
              <min>0.2</min>
              <max>15</max>
            </range>
            <noise>
              <type>gaussian</type>
              <mean>0</mean>
              <stddev>0.03</stddev>
            </noise>
          </ray>
          <plugin name='laser_controller' filename='libgazebo_ros_laser.so'>
            <topicName>/scan</topicName>
            <frameName>laser_frame</frameName>
            <robotNamespace>/</robotNamespace>
          </plugin>
          <pose>0 0 0.005 0 -0 0</pose>
        </sensor>
        <self_collide>0</self_collide>
        <enable_wind>0</enable_wind>
        <kinematic>0</kinematic>
      </link>
      <joint name='FL1_joint' type='revolute'>
        <pose relative_to='base_link'>0.0954 0.04 0 1.5708 0 -1.5708</pose>
        <parent>base_link</parent>
        <child>FL1</child>
        <axis>
          <xyz>0 0 1</xyz>
          <limit>
            <lower>-3</lower>
            <upper>3</upper>
            <effort>1.4</effort>
            <velocity>3</velocity>
          </limit>
          <dynamics>
            <spring_reference>0</spring_reference>
            <spring_stiffness>0</spring_stiffness>
          </dynamics>
        </axis>
      </joint>
      <link name='FL1'>
        <pose relative_to='FL1_joint'>0 0 0 0 -0 0</pose>
        <inertial>
          <pose>-0.011124 -0.003281 0.000145 0 -0 0</pose>
          <mass>0.15334</mass>
          <inertia>
            <ixx>4.4732e-05</ixx>
            <ixy>1.0746e-05</ixy>
            <ixz>1.7651e-07</ixz>
            <iyy>4.3482e-05</iyy>
            <iyz>-7.8105e-08</iyz>
            <izz>6.8645e-05</izz>
          </inertia>
        </inertial>
        <visual name='FL1_visual'>
          <pose>0 0 0 0 -0 0</pose>
          <geometry>
            <mesh>
              <scale>1 1 1</scale>
              <uri>/home/liamo/Quadruped-Robot-Project/notspot_sim_py/src/notspot_description/meshes/FL1_obj.obj</uri>
            </mesh>
          </geometry>
        </visual>
        <self_collide>0</self_collide>
        <enable_wind>0</enable_wind>
        <kinematic>0</kinematic>
      </link>
      <joint name='FL2_joint' type='revolute'>
        <pose relative_to='FL1'>-0.0469 0 0 1.5708 0 -1.5708</pose>
        <parent>FL1</parent>
        <child>FL2</child>
        <axis>
          <xyz>0 0 1</xyz>
          <limit>
            <lower>-3</lower>
            <upper>3</upper>
            <effort>1.4</effort>
            <velocity>3</velocity>
          </limit>
          <dynamics>
            <spring_reference>0</spring_reference>
            <spring_stiffness>0</spring_stiffness>
          </dynamics>
        </axis>
      </joint>
      <link name='FL2'>
        <pose relative_to='FL2_joint'>0 0 0 0 -0 0</pose>
        <inertial>
          <pose>0.038603 -0.002558 0.000175 0 -0 0</pose>
          <mass>0.15106</mass>
          <inertia>
            <ixx>2.365e-05</ixx>
            <ixy>-5.3771e-07</ixy>
            <ixz>1.6144e-06</ixz>
            <iyy>0.00010469</iyy>
            <iyz>-8.306e-08</iyz>
            <izz>0.00011187</izz>
          </inertia>
        </inertial>
        <collision name='FL2_collision'>
          <pose>0.04 0 0 3.14159 1.57079 3.14159</pose>
          <geometry>
            <cylinder>
              <length>0.125</length>
              <radius>0.014</radius>
            </cylinder>
          </geometry>
          <max_contacts>10</max_contacts>
          <surface>
            <contact>
              <ode/>
            </contact>
            <bounce/>
            <friction>
              <torsional>
                <ode/>
              </torsional>
              <ode/>
            </friction>
          </surface>
        </collision>
        <visual name='FL2_visual'>
          <pose>0 0 0 0 -0 0</pose>
          <geometry>
            <mesh>
              <scale>1 1 1</scale>
              <uri>/home/liamo/Quadruped-Robot-Project/notspot_sim_py/src/notspot_description/meshes/L2_obj.obj</uri>
            </mesh>
          </geometry>
        </visual>
        <self_collide>0</self_collide>
        <enable_wind>0</enable_wind>
        <kinematic>0</kinematic>
      </link>
      <joint name='FL3_joint' type='revolute'>
        <pose relative_to='FL2'>0.1 0 0 0 -0 0</pose>
        <parent>FL2</parent>
        <child>FL3</child>
        <axis>
          <xyz>0 0 1</xyz>
          <limit>
            <lower>-3</lower>
            <upper>3</upper>
            <effort>1.4</effort>
            <velocity>3</velocity>
          </limit>
          <dynamics>
            <spring_reference>0</spring_reference>
            <spring_stiffness>0</spring_stiffness>
          </dynamics>
        </axis>
      </joint>
      <link name='FL3'>
        <pose relative_to='FL3_joint'>0 0 0 0 -0 0</pose>
        <inertial>
          <pose>0.070189 -0.00037 3.5e-05 0 -0 0</pose>
          <mass>0.062472</mass>
          <inertia>
            <ixx>6.70917e-07</ixx>
            <ixy>-2.52282e-07</ixy>
            <ixz>1.9259e-07</ixz>
            <iyy>8.81815e-05</iyy>
            <iyz>-2.57711e-09</iyz>
            <izz>8.84077e-05</izz>
          </inertia>
        </inertial>
        <collision name='FL3_collision'>
          <pose>0.045 0 0 3.14159 1.57079 3.14159</pose>
          <geometry>
            <cylinder>
              <length>0.06</length>
              <radius>0.007</radius>
            </cylinder>
          </geometry>
          <max_contacts>10</max_contacts>
          <surface>
            <contact>
              <ode/>
            </contact>
            <bounce/>
            <friction>
              <torsional>
                <ode/>
              </torsional>
              <ode/>
            </friction>
          </surface>
        </collision>
        <collision name='FL3_fixed_joint_lump__FL4_collision_1'>
          <pose>0.094333 0 0 0 -0 0</pose>
          <geometry>
            <sphere>
              <radius>0.0072</radius>
            </sphere>
          </geometry>
          <surface>
            <contact>
              <ode>
                <kp>1e+06</kp>
                <kd>100</kd>
                <min_depth>0.0002</min_depth>
              </ode>
            </contact>
            <friction>
              <ode>
                <mu>1</mu>
                <mu2>1</mu2>
              </ode>
              <torsional>
                <ode/>
              </torsional>
            </friction>
            <bounce/>
          </surface>
          <max_contacts>10</max_contacts>
        </collision>
        <visual name='FL3_visual'>
          <pose>0 0 0 0 -0 0</pose>
          <geometry>
            <mesh>
              <scale>1 1 1</scale>
              <uri>/home/liamo/Quadruped-Robot-Project/notspot_sim_py/src/notspot_description/meshes/L3_obj.obj</uri>
            </mesh>
          </geometry>
        </visual>
        <self_collide>0</self_collide>
        <enable_wind>0</enable_wind>
        <kinematic>0</kinematic>
      </link>
      <joint name='FR1_joint' type='revolute'>
        <pose relative_to='base_link'>0.0954 -0.04 0 1.5708 0 -1.5708</pose>
        <parent>base_link</parent>
        <child>FR1</child>
        <axis>
          <xyz>0 0 1</xyz>
          <limit>
            <lower>-3</lower>
            <upper>3</upper>
            <effort>1.4</effort>
            <velocity>3</velocity>
          </limit>
          <dynamics>
            <spring_reference>0</spring_reference>
            <spring_stiffness>0</spring_stiffness>
          </dynamics>
        </axis>
      </joint>
      <link name='FR1'>
        <pose relative_to='FR1_joint'>0 0 0 0 -0 0</pose>
        <inertial>
          <pose>0.011092 -0.003272 0.000193 0 -0 0</pose>
          <mass>0.15379</mass>
          <inertia>
            <ixx>4.474e-05</ixx>
            <ixy>-1.0746e-05</ixy>
            <ixz>-1.7651e-07</ixz>
            <iyy>4.3489e-05</iyy>
            <iyz>-7.8105e-08</iyz>
            <izz>6.8646e-05</izz>
          </inertia>
        </inertial>
        <visual name='FR1_visual'>
          <pose>0 0 0 0 -0 0</pose>
          <geometry>
            <mesh>
              <scale>1 1 1</scale>
              <uri>/home/liamo/Quadruped-Robot-Project/notspot_sim_py/src/notspot_description/meshes/FR1_obj.obj</uri>
            </mesh>
          </geometry>
        </visual>
        <self_collide>0</self_collide>
        <enable_wind>0</enable_wind>
        <kinematic>0</kinematic>
      </link>
      <joint name='FR2_joint' type='revolute'>
        <pose relative_to='FR1'>0.0469 0 0 1.5708 0 -1.5708</pose>
        <parent>FR1</parent>
        <child>FR2</child>
        <axis>
          <xyz>0 0 1</xyz>
          <limit>
            <lower>-3</lower>
            <upper>3</upper>
            <effort>1.4</effort>
            <velocity>3</velocity>
          </limit>
          <dynamics>
            <spring_reference>0</spring_reference>
            <spring_stiffness>0</spring_stiffness>
          </dynamics>
        </axis>
      </joint>
      <link name='FR2'>
        <pose relative_to='FR2_joint'>0 0 0 0 -0 0</pose>
        <inertial>
          <pose>0.038603 -0.002558 -0.000175 0 -0 0</pose>
          <mass>0.15106</mass>
          <inertia>
            <ixx>2.365e-05</ixx>
            <ixy>-5.3771e-07</ixy>
            <ixz>-1.6144e-06</ixz>
            <iyy>0.00010469</iyy>
            <iyz>8.3059e-08</iyz>
            <izz>0.00011187</izz>
          </inertia>
        </inertial>
        <collision name='FR2_collision'>
          <pose>0.04 0 0 3.14159 1.57079 3.14159</pose>
          <geometry>
            <cylinder>
              <length>0.125</length>
              <radius>0.014</radius>
            </cylinder>
          </geometry>
          <max_contacts>10</max_contacts>
          <surface>
            <contact>
              <ode/>
            </contact>
            <bounce/>
            <friction>
              <torsional>
                <ode/>
              </torsional>
              <ode/>
            </friction>
          </surface>
        </collision>
        <visual name='FR2_visual'>
          <pose>0 0 0 0 -0 0</pose>
          <geometry>
            <mesh>
              <scale>1 1 1</scale>
              <uri>/home/liamo/Quadruped-Robot-Project/notspot_sim_py/src/notspot_description/meshes/R2_obj.obj</uri>
            </mesh>
          </geometry>
        </visual>
        <self_collide>0</self_collide>
        <enable_wind>0</enable_wind>
        <kinematic>0</kinematic>
      </link>
      <joint name='FR3_joint' type='revolute'>
        <pose relative_to='FR2'>0.1 0 0 0 -0 0</pose>
        <parent>FR2</parent>
        <child>FR3</child>
        <axis>
          <xyz>0 0 1</xyz>
          <limit>
            <lower>-3</lower>
            <upper>3</upper>
            <effort>1.4</effort>
            <velocity>3</velocity>
          </limit>
          <dynamics>
            <spring_reference>0</spring_reference>
            <spring_stiffness>0</spring_stiffness>
          </dynamics>
        </axis>
      </joint>
      <link name='FR3'>
        <pose relative_to='FR3_joint'>0 0 0 0 -0 0</pose>
        <inertial>
          <pose>0.070189 -0.00037 -3.5e-05 0 -0 0</pose>
          <mass>0.062472</mass>
          <inertia>
            <ixx>6.70917e-07</ixx>
            <ixy>-2.52263e-07</ixy>
            <ixz>-1.92589e-07</ixz>
            <iyy>8.81815e-05</iyy>
            <iyz>2.57716e-09</iyz>
            <izz>8.84077e-05</izz>
          </inertia>
        </inertial>
        <collision name='FR3_collision'>
          <pose>0.045 0 0 3.14159 1.57079 3.14159</pose>
          <geometry>
            <cylinder>
              <length>0.06</length>
              <radius>0.007</radius>
            </cylinder>
          </geometry>
          <max_contacts>10</max_contacts>
          <surface>
            <contact>
              <ode/>
            </contact>
            <bounce/>
            <friction>
              <torsional>
                <ode/>
              </torsional>
              <ode/>
            </friction>
          </surface>
        </collision>
        <collision name='FR3_fixed_joint_lump__FR4_collision_1'>
          <pose>0.094333 0 0 0 -0 0</pose>
          <geometry>
            <sphere>
              <radius>0.0072</radius>
            </sphere>
          </geometry>
          <surface>
            <contact>
              <ode>
                <kp>1e+06</kp>
                <kd>100</kd>
                <min_depth>0.0002</min_depth>
              </ode>
            </contact>
            <friction>
              <ode>
                <mu>1</mu>
                <mu2>1</mu2>
              </ode>
              <torsional>
                <ode/>
              </torsional>
            </friction>
            <bounce/>
          </surface>
          <max_contacts>10</max_contacts>
        </collision>
        <visual name='FR3_visual'>
          <pose>0 0 0 0 -0 0</pose>
          <geometry>
            <mesh>
              <scale>1 1 1</scale>
              <uri>/home/liamo/Quadruped-Robot-Project/notspot_sim_py/src/notspot_description/meshes/R3_obj.obj</uri>
            </mesh>
          </geometry>
        </visual>
        <self_collide>0</self_collide>
        <enable_wind>0</enable_wind>
        <kinematic>0</kinematic>
      </link>
      <joint name='RL1_joint' type='revolute'>
        <pose relative_to='base_link'>-0.0954 0.04 0 1.5708 0 -1.5708</pose>
        <parent>base_link</parent>
        <child>RL1</child>
        <axis>
          <xyz>0 0 1</xyz>
          <limit>
            <lower>-3</lower>
            <upper>3</upper>
            <effort>1.4</effort>
            <velocity>3</velocity>
          </limit>
          <dynamics>
            <spring_reference>0</spring_reference>
            <spring_stiffness>0</spring_stiffness>
          </dynamics>
        </axis>
      </joint>
      <link name='RL1'>
        <pose relative_to='RL1_joint'>0 0 0 0 -0 0</pose>
        <inertial>
          <pose>-0.011092 -0.003272 -0.000193 0 -0 0</pose>
          <mass>0.15379</mass>
          <inertia>
            <ixx>4.474e-05</ixx>
            <ixy>1.0746e-05</ixy>
            <ixz>-1.7651e-07</ixz>
            <iyy>4.3489e-05</iyy>
            <iyz>7.8105e-08</iyz>
            <izz>6.8646e-05</izz>
          </inertia>
        </inertial>
        <visual name='RL1_visual'>
          <pose>0 0 0 0 -0 0</pose>
          <geometry>
            <mesh>
              <scale>1 1 1</scale>
              <uri>/home/liamo/Quadruped-Robot-Project/notspot_sim_py/src/notspot_description/meshes/RL1_obj.obj</uri>
            </mesh>
          </geometry>
        </visual>
        <self_collide>0</self_collide>
        <enable_wind>0</enable_wind>
        <kinematic>0</kinematic>
      </link>
      <joint name='RL2_joint' type='revolute'>
        <pose relative_to='RL1'>-0.0469 0 0 1.5708 0 -1.5708</pose>
        <parent>RL1</parent>
        <child>RL2</child>
        <axis>
          <xyz>0 0 1</xyz>
          <limit>
            <lower>-3</lower>
            <upper>3</upper>
            <effort>1.4</effort>
            <velocity>3</velocity>
          </limit>
          <dynamics>
            <spring_reference>0</spring_reference>
            <spring_stiffness>0</spring_stiffness>
          </dynamics>
        </axis>
      </joint>
      <link name='RL2'>
        <pose relative_to='RL2_joint'>0 0 0 0 -0 0</pose>
        <inertial>
          <pose>0.038603 -0.002558 0.000175 0 -0 0</pose>
          <mass>0.15106</mass>
          <inertia>
            <ixx>2.365e-05</ixx>
            <ixy>-5.3771e-07</ixy>
            <ixz>1.6144e-06</ixz>
            <iyy>0.00010469</iyy>
            <iyz>-8.306e-08</iyz>
            <izz>0.00011187</izz>
          </inertia>
        </inertial>
        <collision name='RL2_collision'>
          <pose>0.04 0 0 3.14159 1.57079 3.14159</pose>
          <geometry>
            <cylinder>
              <length>0.125</length>
              <radius>0.014</radius>
            </cylinder>
          </geometry>
          <max_contacts>10</max_contacts>
          <surface>
            <contact>
              <ode/>
            </contact>
            <bounce/>
            <friction>
              <torsional>
                <ode/>
              </torsional>
              <ode/>
            </friction>
          </surface>
        </collision>
        <visual name='RL2_visual'>
          <pose>0 0 0 0 -0 0</pose>
          <geometry>
            <mesh>
              <scale>1 1 1</scale>
              <uri>/home/liamo/Quadruped-Robot-Project/notspot_sim_py/src/notspot_description/meshes/L2_obj.obj</uri>
            </mesh>
          </geometry>
        </visual>
        <self_collide>0</self_collide>
        <enable_wind>0</enable_wind>
        <kinematic>0</kinematic>
      </link>
      <joint name='RL3_joint' type='revolute'>
        <pose relative_to='RL2'>0.1 0 0 0 -0 0</pose>
        <parent>RL2</parent>
        <child>RL3</child>
        <axis>
          <xyz>0 0 1</xyz>
          <limit>
            <lower>-3</lower>
            <upper>3</upper>
            <effort>1.4</effort>
            <velocity>3</velocity>
          </limit>
          <dynamics>
            <spring_reference>0</spring_reference>
            <spring_stiffness>0</spring_stiffness>
          </dynamics>
        </axis>
      </joint>
      <link name='RL3'>
        <pose relative_to='RL3_joint'>0 0 0 0 -0 0</pose>
        <inertial>
          <pose>0.070189 -0.00037 3.5e-05 0 -0 0</pose>
          <mass>0.062472</mass>
          <inertia>
            <ixx>6.70917e-07</ixx>
            <ixy>-2.52282e-07</ixy>
            <ixz>1.9259e-07</ixz>
            <iyy>8.81815e-05</iyy>
            <iyz>-2.57711e-09</iyz>
            <izz>8.84077e-05</izz>
          </inertia>
        </inertial>
        <collision name='RL3_collision'>
          <pose>0.045 0 0 3.14159 1.57079 3.14159</pose>
          <geometry>
            <cylinder>
              <length>0.06</length>
              <radius>0.007</radius>
            </cylinder>
          </geometry>
          <max_contacts>10</max_contacts>
          <surface>
            <contact>
              <ode/>
            </contact>
            <bounce/>
            <friction>
              <torsional>
                <ode/>
              </torsional>
              <ode/>
            </friction>
          </surface>
        </collision>
        <collision name='RL3_fixed_joint_lump__RL4_collision_1'>
          <pose>0.094333 0 0 0 -0 0</pose>
          <geometry>
            <sphere>
              <radius>0.0072</radius>
            </sphere>
          </geometry>
          <surface>
            <contact>
              <ode>
                <kp>1e+06</kp>
                <kd>100</kd>
                <min_depth>0.0002</min_depth>
              </ode>
            </contact>
            <friction>
              <ode>
                <mu>1</mu>
                <mu2>1</mu2>
              </ode>
              <torsional>
                <ode/>
              </torsional>
            </friction>
            <bounce/>
          </surface>
          <max_contacts>10</max_contacts>
        </collision>
        <visual name='RL3_visual'>
          <pose>0 0 0 0 -0 0</pose>
          <geometry>
            <mesh>
              <scale>1 1 1</scale>
              <uri>/home/liamo/Quadruped-Robot-Project/notspot_sim_py/src/notspot_description/meshes/L3_obj.obj</uri>
            </mesh>
          </geometry>
        </visual>
        <self_collide>0</self_collide>
        <enable_wind>0</enable_wind>
        <kinematic>0</kinematic>
      </link>
      <joint name='RR1_joint' type='revolute'>
        <pose relative_to='base_link'>-0.0954 -0.04 0 1.5708 0 -1.5708</pose>
        <parent>base_link</parent>
        <child>RR1</child>
        <axis>
          <xyz>0 0 1</xyz>
          <limit>
            <lower>-3</lower>
            <upper>3</upper>
            <effort>1.4</effort>
            <velocity>3</velocity>
          </limit>
          <dynamics>
            <spring_reference>0</spring_reference>
            <spring_stiffness>0</spring_stiffness>
          </dynamics>
        </axis>
      </joint>
      <link name='RR1'>
        <pose relative_to='RR1_joint'>0 0 0 0 -0 0</pose>
        <inertial>
          <pose>0.011092 -0.003272 -0.000193 0 -0 0</pose>
          <mass>0.15379</mass>
          <inertia>
            <ixx>4.474e-05</ixx>
            <ixy>-1.0746e-05</ixy>
            <ixz>1.7651e-07</ixz>
            <iyy>4.3489e-05</iyy>
            <iyz>7.8105e-08</iyz>
            <izz>6.8646e-05</izz>
          </inertia>
        </inertial>
        <visual name='RR1_visual'>
          <pose>0 0 0 0 -0 0</pose>
          <geometry>
            <mesh>
              <scale>1 1 1</scale>
              <uri>/home/liamo/Quadruped-Robot-Project/notspot_sim_py/src/notspot_description/meshes/RR1_obj.obj</uri>
            </mesh>
          </geometry>
        </visual>
        <self_collide>0</self_collide>
        <enable_wind>0</enable_wind>
        <kinematic>0</kinematic>
      </link>
      <joint name='RR2_joint' type='revolute'>
        <pose relative_to='RR1'>0.0469 0 0 1.5708 0 -1.5708</pose>
        <parent>RR1</parent>
        <child>RR2</child>
        <axis>
          <xyz>0 0 1</xyz>
          <limit>
            <lower>-3</lower>
            <upper>3</upper>
            <effort>1.4</effort>
            <velocity>3</velocity>
          </limit>
          <dynamics>
            <spring_reference>0</spring_reference>
            <spring_stiffness>0</spring_stiffness>
          </dynamics>
        </axis>
      </joint>
      <link name='RR2'>
        <pose relative_to='RR2_joint'>0 0 0 0 -0 0</pose>
        <inertial>
          <pose>0.038603 -0.002558 -0.000175 0 -0 0</pose>
          <mass>0.15106</mass>
          <inertia>
            <ixx>2.365e-05</ixx>
            <ixy>-5.3771e-07</ixy>
            <ixz>-1.6144e-06</ixz>
            <iyy>0.00010469</iyy>
            <iyz>8.3059e-08</iyz>
            <izz>0.00011187</izz>
          </inertia>
        </inertial>
        <collision name='RR2_collision'>
          <pose>0.04 0 0 3.14159 1.57079 3.14159</pose>
          <geometry>
            <cylinder>
              <length>0.125</length>
              <radius>0.014</radius>
            </cylinder>
          </geometry>
          <max_contacts>10</max_contacts>
          <surface>
            <contact>
              <ode/>
            </contact>
            <bounce/>
            <friction>
              <torsional>
                <ode/>
              </torsional>
              <ode/>
            </friction>
          </surface>
        </collision>
        <visual name='RR2_visual'>
          <pose>0 0 0 0 -0 0</pose>
          <geometry>
            <mesh>
              <scale>1 1 1</scale>
              <uri>/home/liamo/Quadruped-Robot-Project/notspot_sim_py/src/notspot_description/meshes/R2_obj.obj</uri>
            </mesh>
          </geometry>
        </visual>
        <self_collide>0</self_collide>
        <enable_wind>0</enable_wind>
        <kinematic>0</kinematic>
      </link>
      <joint name='RR3_joint' type='revolute'>
        <pose relative_to='RR2'>0.1 0 0 0 -0 0</pose>
        <parent>RR2</parent>
        <child>RR3</child>
        <axis>
          <xyz>0 0 1</xyz>
          <limit>
            <lower>-3</lower>
            <upper>3</upper>
            <effort>1.4</effort>
            <velocity>3</velocity>
          </limit>
          <dynamics>
            <spring_reference>0</spring_reference>
            <spring_stiffness>0</spring_stiffness>
          </dynamics>
        </axis>
      </joint>
      <link name='RR3'>
        <pose relative_to='RR3_joint'>0 0 0 0 -0 0</pose>
        <inertial>
          <pose>0.070189 -0.00037 -3.5e-05 0 -0 0</pose>
          <mass>0.062472</mass>
          <inertia>
            <ixx>6.70917e-07</ixx>
            <ixy>-2.52263e-07</ixy>
            <ixz>-1.92589e-07</ixz>
            <iyy>8.81815e-05</iyy>
            <iyz>2.57716e-09</iyz>
            <izz>8.84077e-05</izz>
          </inertia>
        </inertial>
        <collision name='RR3_collision'>
          <pose>0.045 0 0 3.14159 1.57079 3.14159</pose>
          <geometry>
            <cylinder>
              <length>0.06</length>
              <radius>0.007</radius>
            </cylinder>
          </geometry>
          <max_contacts>10</max_contacts>
          <surface>
            <contact>
              <ode/>
            </contact>
            <bounce/>
            <friction>
              <torsional>
                <ode/>
              </torsional>
              <ode/>
            </friction>
          </surface>
        </collision>
        <collision name='RR3_fixed_joint_lump__RR4_collision_1'>
          <pose>0.094333 0 0 0 -0 0</pose>
          <geometry>
            <sphere>
              <radius>0.0072</radius>
            </sphere>
          </geometry>
          <surface>
            <contact>
              <ode>
                <kp>1e+06</kp>
                <kd>100</kd>
                <min_depth>0.0002</min_depth>
              </ode>
            </contact>
            <friction>
              <ode>
                <mu>1</mu>
                <mu2>1</mu2>
              </ode>
              <torsional>
                <ode/>
              </torsional>
            </friction>
            <bounce/>
          </surface>
          <max_contacts>10</max_contacts>
        </collision>
        <visual name='RR3_visual'>
          <pose>0 0 0 0 -0 0</pose>
          <geometry>
            <mesh>
              <scale>1 1 1</scale>
              <uri>/home/liamo/Quadruped-Robot-Project/notspot_sim_py/src/notspot_description/meshes/R3_obj.obj</uri>
            </mesh>
          </geometry>
        </visual>
        <self_collide>0</self_collide>
        <enable_wind>0</enable_wind>
        <kinematic>0</kinematic>
      </link>
      <plugin name='gazebo_ros_control' filename='libgazebo_ros_control.so'>
        <robotNamespace>notspot_controller</robotNamespace>
      </plugin>
      <plugin name='joint_state_publisher' filename='libgazebo_ros_joint_state_publisher.so'>
        <robotNamespace>notspot_gazebo</robotNamespace>
        <jointName>FR1_joint, FR2_joint, FR3_joint, FL1_joint, FL2_joint, FL3_joint, RR1_joint, RR2_joint, RR3_joint, RL1_joint, RL2_joint, RL3_joint</jointName>
        <updateRate>100</updateRate>
      </plugin>
      <plugin name='gazebo_ros_control' filename='libgazebo_ros_control.so'>
        <robotNamespace>/notspot</robotNamespace>
        <robotSimType>gazebo_ros_control/DefaultRobotHWSim</robotSimType>
        <legacyModeNS>1</legacyModeNS>
      </plugin>
      <plugin name='gazebo_ros_control' filename='libgazebo_ros_control.so'>
        <robotNamespace>/</robotNamespace>
      </plugin>
      <frame name='camera_optical_joint' attached_to='camera_link'>
        <pose>0 0 0 -1.5708 -0 -1.5708</pose>
      </frame>
      <frame name='camera_link_optical' attached_to='camera_optical_joint'/>
      <frame name='camera_joint' attached_to='base_link'>
        <pose>0.13 0 0.005 0 -0 0</pose>
      </frame>
      <frame name='camera_link' attached_to='camera_joint'/>
      <frame name='laser_joint' attached_to='base_link'>
        <pose>0 0 0.005 0 -0 0</pose>
      </frame>
      <frame name='laser_frame' attached_to='laser_joint'/>
      <frame name='FL4_joint' attached_to='FL3'>
        <pose>0.094333 0 0 0 -0 0</pose>
      </frame>
      <frame name='FL4' attached_to='FL4_joint'/>
      <frame name='FR4_joint' attached_to='FR3'>
        <pose>0.094333 0 0 0 -0 0</pose>
      </frame>
      <frame name='FR4' attached_to='FR4_joint'/>
      <frame name='RL4_joint' attached_to='RL3'>
        <pose>0.094333 0 0 0 -0 0</pose>
      </frame>
      <frame name='RL4' attached_to='RL4_joint'/>
      <frame name='RR4_joint' attached_to='RR3'>
        <pose>0.094333 0 0 0 -0 0</pose>
      </frame>
      <frame name='RR4' attached_to='RR4_joint'/>
      <pose>0 0 0.5 0 -0 0</pose>
    </model>
    <model name='Simple_House.world'>
      <pose>2.64 -3.87 0 0 -0 0</pose>
      <link name='Wall_0'>
        <pose>-3.55 4.5 0 0 -0 1.5708</pose>
        <visual name='Wall_0_Visual_0'>
          <pose>-1.35509 0 1.25 0 -0 0</pose>
          <geometry>
            <box>
              <size>0.539819 0.15 2.5</size>
            </box>
          </geometry>
          <material>
            <script>
              <uri>file://media/materials/scripts/gazebo.material</uri>
              <name>Gazebo/Grey</name>
            </script>
            <ambient>1 1 1 1</ambient>
          </material>
          <meta>
            <layer>0</layer>
          </meta>
        </visual>
        <collision name='Wall_0_Collision_0'>
          <geometry>
            <box>
              <size>0.539819 0.15 2.5</size>
            </box>
          </geometry>
          <pose>-1.35509 0 1.25 0 -0 0</pose>
          <max_contacts>10</max_contacts>
          <surface>
            <contact>
              <ode/>
            </contact>
            <bounce/>
            <friction>
              <torsional>
                <ode/>
              </torsional>
              <ode/>
            </friction>
          </surface>
        </collision>
        <visual name='Wall_0_Visual_1'>
          <pose>0.719909 0 1.25 0 -0 0</pose>
          <geometry>
            <box>
              <size>1.81018 0.15 2.5</size>
            </box>
          </geometry>
          <material>
            <script>
              <uri>file://media/materials/scripts/gazebo.material</uri>
              <name>Gazebo/Grey</name>
            </script>
            <ambient>1 1 1 1</ambient>
          </material>
          <meta>
            <layer>0</layer>
          </meta>
        </visual>
        <collision name='Wall_0_Collision_1'>
          <geometry>
            <box>
              <size>1.81018 0.15 2.5</size>
            </box>
          </geometry>
          <pose>0.719909 0 1.25 0 -0 0</pose>
          <max_contacts>10</max_contacts>
          <surface>
            <contact>
              <ode/>
            </contact>
            <bounce/>
            <friction>
              <torsional>
                <ode/>
              </torsional>
              <ode/>
            </friction>
          </surface>
        </collision>
        <visual name='Wall_0_Visual_2'>
          <pose>-0.635181 0 2.25 0 -0 0</pose>
          <geometry>
            <box>
              <size>0.9 0.15 0.5</size>
            </box>
          </geometry>
          <material>
            <script>
              <uri>file://media/materials/scripts/gazebo.material</uri>
              <name>Gazebo/Grey</name>
            </script>
            <ambient>1 1 1 1</ambient>
          </material>
          <meta>
            <layer>0</layer>
          </meta>
        </visual>
        <collision name='Wall_0_Collision_2'>
          <geometry>
            <box>
              <size>0.9 0.15 0.5</size>
            </box>
          </geometry>
          <pose>-0.635181 0 2.25 0 -0 0</pose>
          <max_contacts>10</max_contacts>
          <surface>
            <contact>
              <ode/>
            </contact>
            <bounce/>
            <friction>
              <torsional>
                <ode/>
              </torsional>
              <ode/>
            </friction>
          </surface>
        </collision>
        <self_collide>0</self_collide>
        <enable_wind>0</enable_wind>
        <kinematic>0</kinematic>
      </link>
      <link name='Wall_1'>
        <pose>-0 6.05 0 0 -0 0</pose>
        <visual name='Wall_1_Visual_0'>
          <pose>-1.93219 0 1.25 0 -0 0</pose>
          <geometry>
            <box>
              <size>3.38561 0.15 2.5</size>
            </box>
          </geometry>
          <material>
            <script>
              <uri>file://media/materials/scripts/gazebo.material</uri>
              <name>Gazebo/Grey</name>
            </script>
            <ambient>1 1 1 1</ambient>
          </material>
          <meta>
            <layer>0</layer>
          </meta>
        </visual>
        <collision name='Wall_1_Collision_0'>
          <geometry>
            <box>
              <size>3.38561 0.15 2.5</size>
            </box>
          </geometry>
          <pose>-1.93219 0 1.25 0 -0 0</pose>
          <max_contacts>10</max_contacts>
          <surface>
            <contact>
              <ode/>
            </contact>
            <bounce/>
            <friction>
              <torsional>
                <ode/>
              </torsional>
              <ode/>
            </friction>
          </surface>
        </collision>
        <visual name='Wall_1_Visual_1'>
          <pose>1.69281 0 0.25 0 -0 0</pose>
          <geometry>
            <box>
              <size>3.86439 0.15 0.5</size>
            </box>
          </geometry>
          <material>
            <script>
              <uri>file://media/materials/scripts/gazebo.material</uri>
              <name>Gazebo/Grey</name>
            </script>
            <ambient>1 1 1 1</ambient>
          </material>
          <meta>
            <layer>0</layer>
          </meta>
        </visual>
        <collision name='Wall_1_Collision_1'>
          <geometry>
            <box>
              <size>3.86439 0.15 0.5</size>
            </box>
          </geometry>
          <pose>1.69281 0 0.25 0 -0 0</pose>
          <max_contacts>10</max_contacts>
          <surface>
            <contact>
              <ode/>
            </contact>
            <bounce/>
            <friction>
              <torsional>
                <ode/>
              </torsional>
              <ode/>
            </friction>
          </surface>
        </collision>
        <visual name='Wall_1_Visual_2'>
          <pose>2.09281 0 1.5 0 -0 0</pose>
          <geometry>
            <box>
              <size>3.06439 0.15 2</size>
            </box>
          </geometry>
          <material>
            <script>
              <uri>file://media/materials/scripts/gazebo.material</uri>
              <name>Gazebo/Grey</name>
            </script>
            <ambient>1 1 1 1</ambient>
          </material>
          <meta>
            <layer>0</layer>
          </meta>
        </visual>
        <collision name='Wall_1_Collision_2'>
          <geometry>
            <box>
              <size>3.06439 0.15 2</size>
            </box>
          </geometry>
          <pose>2.09281 0 1.5 0 -0 0</pose>
          <max_contacts>10</max_contacts>
          <surface>
            <contact>
              <ode/>
            </contact>
            <bounce/>
            <friction>
              <torsional>
                <ode/>
              </torsional>
              <ode/>
            </friction>
          </surface>
        </collision>
        <visual name='Wall_1_Visual_3'>
          <pose>0.160613 0 1.9 0 -0 0</pose>
          <geometry>
            <box>
              <size>0.8 0.15 1.2</size>
            </box>
          </geometry>
          <material>
            <script>
              <uri>file://media/materials/scripts/gazebo.material</uri>
              <name>Gazebo/Grey</name>
            </script>
            <ambient>1 1 1 1</ambient>
          </material>
          <meta>
            <layer>0</layer>
          </meta>
        </visual>
        <collision name='Wall_1_Collision_3'>
          <geometry>
            <box>
              <size>0.8 0.15 1.2</size>
            </box>
          </geometry>
          <pose>0.160613 0 1.9 0 -0 0</pose>
          <max_contacts>10</max_contacts>
          <surface>
            <contact>
              <ode/>
            </contact>
            <bounce/>
            <friction>
              <torsional>
                <ode/>
              </torsional>
              <ode/>
            </friction>
          </surface>
        </collision>
        <self_collide>0</self_collide>
        <enable_wind>0</enable_wind>
        <kinematic>0</kinematic>
      </link>
      <link name='Wall_2'>
        <collision name='Wall_2_Collision'>
          <geometry>
            <box>
              <size>12.25 0.15 2.5</size>
            </box>
          </geometry>
          <pose>0 0 1.25 0 -0 0</pose>
          <max_contacts>10</max_contacts>
          <surface>
            <contact>
              <ode/>
            </contact>
            <bounce/>
            <friction>
              <torsional>
                <ode/>
              </torsional>
              <ode/>
            </friction>
          </surface>
        </collision>
        <visual name='Wall_2_Visual'>
          <pose>0 0 1.25 0 -0 0</pose>
          <geometry>
            <box>
              <size>12.25 0.15 2.5</size>
            </box>
          </geometry>
          <material>
            <script>
              <uri>file://media/materials/scripts/gazebo.material</uri>
              <name>Gazebo/Grey</name>
            </script>
            <ambient>1 1 1 1</ambient>
          </material>
          <meta>
            <layer>0</layer>
          </meta>
        </visual>
        <pose>3.55 0 0 0 -0 -1.5708</pose>
        <self_collide>0</self_collide>
        <enable_wind>0</enable_wind>
        <kinematic>0</kinematic>
      </link>
      <link name='Wall_3'>
        <collision name='Wall_3_Collision'>
          <geometry>
            <box>
              <size>7.25 0.15 2.5</size>
            </box>
          </geometry>
          <pose>0 0 1.25 0 -0 0</pose>
          <max_contacts>10</max_contacts>
          <surface>
            <contact>
              <ode/>
            </contact>
            <bounce/>
            <friction>
              <torsional>
                <ode/>
              </torsional>
              <ode/>
            </friction>
          </surface>
        </collision>
        <visual name='Wall_3_Visual'>
          <pose>0 0 1.25 0 -0 0</pose>
          <geometry>
            <box>
              <size>7.25 0.15 2.5</size>
            </box>
          </geometry>
          <material>
            <script>
              <uri>file://media/materials/scripts/gazebo.material</uri>
              <name>Gazebo/Grey</name>
            </script>
            <ambient>1 1 1 1</ambient>
          </material>
          <meta>
            <layer>0</layer>
          </meta>
        </visual>
        <pose>-0 -6.05 0 0 -0 3.14159</pose>
        <self_collide>0</self_collide>
        <enable_wind>0</enable_wind>
        <kinematic>0</kinematic>
      </link>
      <link name='Wall_4'>
        <collision name='Wall_4_Collision'>
          <geometry>
            <box>
              <size>9 0.15 2.5</size>
            </box>
          </geometry>
          <pose>0 0 1.25 0 -0 0</pose>
          <max_contacts>10</max_contacts>
          <surface>
            <contact>
              <ode/>
            </contact>
            <bounce/>
            <friction>
              <torsional>
                <ode/>
              </torsional>
              <ode/>
            </friction>
          </surface>
        </collision>
        <visual name='Wall_4_Visual'>
          <pose>0 0 1.25 0 -0 0</pose>
          <geometry>
            <box>
              <size>9 0.15 2.5</size>
            </box>
          </geometry>
          <material>
            <script>
              <uri>file://media/materials/scripts/gazebo.material</uri>
              <name>Gazebo/Grey</name>
            </script>
            <ambient>1 1 1 1</ambient>
          </material>
          <meta>
            <layer>0</layer>
          </meta>
        </visual>
        <pose>-3.55 -1.625 0 0 -0 1.5708</pose>
        <self_collide>0</self_collide>
        <enable_wind>0</enable_wind>
        <kinematic>0</kinematic>
      </link>
      <static>1</static>
    </model>
    <state world_name='default'>
      <sim_time>34 666000000</sim_time>
      <real_time>54 539545969</real_time>
      <wall_time>1744802872 623678294</wall_time>
      <iterations>34666</iterations>
      <model name='Simple_House.world'>
        <pose>2.64 -3.87 0 0 -0 0</pose>
        <scale>1 1 1</scale>
        <link name='Wall_0'>
          <pose>-0.91 0.63 0 0 -0 1.5708</pose>
          <velocity>0 0 0 0 -0 0</velocity>
          <acceleration>0 0 0 0 -0 0</acceleration>
          <wrench>0 0 0 0 -0 0</wrench>
        </link>
        <link name='Wall_1'>
          <pose>2.64 2.18 0 0 -0 0</pose>
          <velocity>0 0 0 0 -0 0</velocity>
          <acceleration>0 0 0 0 -0 0</acceleration>
          <wrench>0 0 0 0 -0 0</wrench>
        </link>
        <link name='Wall_2'>
          <pose>6.19 -3.87 0 0 0 -1.5708</pose>
          <velocity>0 0 0 0 -0 0</velocity>
          <acceleration>0 0 0 0 -0 0</acceleration>
          <wrench>0 0 0 0 -0 0</wrench>
        </link>
        <link name='Wall_3'>
          <pose>2.64 -9.92 0 0 -0 3.14159</pose>
          <velocity>0 0 0 0 -0 0</velocity>
          <acceleration>0 0 0 0 -0 0</acceleration>
          <wrench>0 0 0 0 -0 0</wrench>
        </link>
        <link name='Wall_4'>
          <pose>-0.91 -5.495 0 0 -0 1.5708</pose>
          <velocity>0 0 0 0 -0 0</velocity>
          <acceleration>0 0 0 0 -0 0</acceleration>
          <wrench>0 0 0 0 -0 0</wrench>
        </link>
      </model>
      <model name='box'>
        <pose>1 1 0 0 0.1 0</pose>
        <scale>1 1 1</scale>
        <link name='link'>
          <pose>1 1 0 0 0.1 0</pose>
          <velocity>0 0 0 0 -0 0</velocity>
          <acceleration>0 0 0 0 -0 0</acceleration>
          <wrench>0 0 0 0 -0 0</wrench>
        </link>
      </model>
      <model name='ground_plane'>
        <pose>0 0 0 0 -0 0</pose>
        <scale>1 1 1</scale>
        <link name='link'>
          <pose>0 0 0 0 -0 0</pose>
          <velocity>0 0 0 0 -0 0</velocity>
          <acceleration>0 0 0 0 -0 0</acceleration>
          <wrench>0 0 0 0 -0 0</wrench>
        </link>
      </model>
      <model name='notspot_gazebo'>
        <pose>0.012147 -0.000744 0.15554 0.000555 -0.007528 -0.023937</pose>
        <scale>1 1 1</scale>
        <link name='FL1'>
          <pose>0.108474 0.036962 0.156281 1.57833 0.00587 -1.59472</pose>
          <velocity>7e-06 -7e-06 2e-06 0.000109 -1.4e-05 -1.2e-05</velocity>
          <acceleration>-0 -0 0 1.93096 -1.13407 -1.41094</acceleration>
          <wrench>-0 -0 0 0 -0 0</wrench>
        </link>
        <link name='FL2'>
          <pose>0.109595 0.083848 0.156557 1.56119 0.916192 3.11001</pose>
          <velocity>8e-06 -7e-06 7e-06 0.000119 0.000365 -9e-06</velocity>
          <acceleration>0 -0 -0 -1.52006 -0.407772 -3.07764</acceleration>
          <wrench>0 -0 -0 0 -0 0</wrench>
        </link>
        <link name='FL3'>
          <pose>0.04874 0.085769 0.077228 -1.56332 0.839822 -0.017828</pose>
          <velocity>-2.1e-05 3e-06 3e-05 0.000132 -0.000269 -3e-05</velocity>
          <acceleration>0 -0 -0 0.811788 -1.18056 -2.96569</acceleration>
          <wrench>0 -0 -0 0 -0 0</wrench>
        </link>
        <link name='FR1'>
          <pose>0.106559 -0.043016 0.156236 1.57832 -0.003986 -1.59473</pose>
          <velocity>6e-06 -7e-06 -0 -7.6e-05 -9e-06 -1.5e-05</velocity>
          <acceleration>-0 -0 0 2.9235 1.55991 -3.02281</acceleration>
          <wrench>-0 -0 0 0 -0 0</wrench>
        </link>
        <link name='FR2'>
          <pose>0.105436 -0.089902 0.156424 1.57723 0.911134 3.12279</pose>
          <velocity>5e-06 -7e-06 3e-06 -6.6e-05 0.000422 -1.7e-05</velocity>
          <acceleration>-0 0 -0 -0.42128 -0.386528 0.111802</acceleration>
          <wrench>-0 0 -0 0 -0 0</wrench>
        </link>
        <link name='FR3'>
          <pose>0.044161 -0.088749 0.077404 -1.57456 0.842643 -0.027627</pose>
          <velocity>-2.8e-05 -1.1e-05 2.9e-05 -0.000108 -0.000371 -1e-06</velocity>
          <acceleration>-0 0 0 -0.484234 0.46186 -0.545708</acceleration>
          <wrench>-0 0 0 0 -0 0</wrench>
        </link>
        <link name='RL1'>
          <pose>-0.082266 0.041528 0.154845 1.57832 0.013289 -1.59465</pose>
          <velocity>7e-06 -4e-06 -0 6.9e-05 -1.3e-05 -1.2e-05</velocity>
          <acceleration>-0 0 0 1.83537 -1.04965 3.09365</acceleration>
          <wrench>-0 0 0 0 -0 0</wrench>
        </link>
        <link name='RL2'>
          <pose>-0.081148 0.088411 0.155469 1.55211 0.781322 3.10455</pose>
          <velocity>8e-06 -4e-06 3e-06 8.2e-05 0.000473 -5e-06</velocity>
          <acceleration>-0 0 -0 -2.15177 -0.149069 1.97369</acceleration>
          <wrench>-0 0 -0 0 -0 0</wrench>
        </link>
        <link name='RL3'>
          <pose>-0.152098 0.09104 0.085047 -1.54812 0.974504 -0.004682</pose>
          <velocity>-2.6e-05 2e-06 3.7e-05 8.6e-05 -0.000298 -3.3e-05</velocity>
          <acceleration>-0 -0 0 0.949121 -1.45932 0.001718</acceleration>
          <wrench>-0 -0 0 0 -0 0</wrench>
        </link>
        <link name='RR1'>
          <pose>-0.084181 -0.038449 0.1548 1.57832 -0.012787 -1.59483</pose>
          <velocity>6e-06 -4e-06 -2e-06 2e-06 -1.2e-05 -1.3e-05</velocity>
          <acceleration>-0 0 0 -3.01016 1.10673 0.585769</acceleration>
          <wrench>-0 0 0 0 -0 0</wrench>
        </link>
        <link name='RR2'>
          <pose>-0.085308 -0.085332 0.1554 1.58874 0.777012 3.13014</pose>
          <velocity>5e-06 -4e-06 -2e-06 1.4e-05 0.000454 -2e-05</velocity>
          <acceleration>-0 0 -0 2.9525 0.974642 1.35303</acceleration>
          <wrench>-0 0 -0 0 -0 0</wrench>
        </link>
        <link name='RR3'>
          <pose>-0.156604 -0.084514 0.085285 -1.59326 0.978993 -0.042866</pose>
          <velocity>-2.6e-05 -2e-06 3e-05 -2.7e-05 -0.00031 6e-06</velocity>
          <acceleration>-0 0 -0 1.41346 -1.18172 -1.66277</acceleration>
          <wrench>-0 0 -0 0 -0 0</wrench>
        </link>
        <link name='base_link'>
          <pose>0.012147 -0.000744 0.15554 0.000555 -0.007528 -0.023937</pose>
          <velocity>7e-06 -5e-06 -0 2.5e-05 -1.2e-05 -1.3e-05</velocity>
          <acceleration>-0 0 0 -0.000682 -0.047274 -0.002566</acceleration>
          <wrench>-0 0 0 0 -0 0</wrench>
        </link>
      </model>
      <light name='sun'>
        <pose>0 0 10 0 -0 0</pose>
      </light>
    </state>
    <gui fullscreen='0'>
      <camera name='user_camera'>
        <pose>7.56801 -6.77651 6.77519 0 0.691643 2.36019</pose>
        <view_controller>orbit</view_controller>
        <projection_type>perspective</projection_type>
      </camera>
    </gui>
  </world>
</sdf>
